Workbook

Sheet README
A1: INFOSYS 3-STATEMENT FINANCIAL MODEL
A3: PROJECT OVERVIEW
A4: Purpose | B4: Three-statement financial model for Infosys using historical FY2025-FY2026 consolidated financials and FY2027-FY2029 forecast assumptions.
A5: Company | B5: Infosys Limited
A6: Financial Statements | B6: Income Statement, Balance Sheet, Cash Flow Statement
A7: Historical Period | B7: FY2025-FY2026
A8: Forecast Period | B8: FY2027-FY2029
A9: Currency / Units | B9: ₹ crore
A11: MODEL STRUCTURE
A12: Assumptions | B12: Forecast drivers and operating assumptions
A13: Income Statement | B13: Historical and forecast profitability
A14: Balance Sheet | B14: Historical and forecast financial position
A15: Cash Flow Statement | B15: Historical and forecast cash generation
A16: 3-Statement Model | B16: Integrated three-statement forecast
A17: Analysis | B17: Financial ratios and model checks
A19: KEY FORECAST ASSUMPTIONS
A20: Revenue Growth | B20: 0.08
A21: Other Income / Revenue | B21: 0.024
A22: Employee Expenses / Revenue | B22: 0.532
A23: Other Operating Expenses / Revenue | B23: 0.225
A24: Depreciation / Revenue | B24: 0.027
A25: Finance Cost / Revenue | B25: 0.002
A26: Tax Rate | B26: 0.263
A27: Capital Expenditure / Revenue | B27: 0.015
A28: Trade Receivables / Revenue | B28: 0.197
A29: Trade Payables / Revenue | B29: 0.027
A30: Dividend Payout Ratio | B30: 0.63
A32: MODEL LIMITATIONS
A33: 1. Forecasts are model estimates, not Infosys management guidance.
A34: 2. Forecast assumptions are simplified and remain constant across the forecast period.
A35: 3. Several Balance Sheet and Cash Flow items are projected using historical ratios or simplified assumptions.
A36: 4. The Balance Sheet reconciliation adjustment is a modeling mechanism used to integrate the three statements.
A37: 5. Detailed taxes, working-capital drivers, acquisitions, buybacks, and investment flows are simplified in the forecast.
A38: 6. Historical financial statements use consolidated Infosys figures reported in the FY2025-26 Annual Report.
A40: SOURCE
A41: Infosys Integrated Annual Report FY2025-26 — Consolidated Financial Statements

Sheet Assumptions
A1: INFOSYS FORECAST ASSUMPTIONS
A3: Assumption | B3: FY2027 | C3: FY2028 | D3: FY2029
A4: Revenue growth | B4: 0.08 | C4: 0.08 | D4: 0.08
A5: Other income / Revenue | B5: 0.024 | C5: 0.024 | D5: 0.024
A6: Employee expenses / Revenue | B6: 0.532 | C6: 0.532 | D6: 0.532
A7: Other operating expenses / Revenue | B7: 0.225 | C7: 0.225 | D7: 0.225
A8: Depreciation / Revenue | B8: 0.027 | C8: 0.027 | D8: 0.027
A9: Finance cost / Revenue | B9: 0.002 | C9: 0.002 | D9: 0.002
A10: Tax rate | B10: 0.263 | C10: 0.263 | D10: 0.263
A11: Capital expenditure / Revenue | B11: 0.015 | C11: 0.015 | D11: 0.015
A12: Trade receivables / Revenue | B12: 0.197 | C12: 0.197 | D12: 0.197
A13: Trade payables / Revenue | B13: 0.027 | C13: 0.027 | D13: 0.027
A14: Dividend payout ratio | B14: 0.63 | C14: 0.63 | D14: 0.63

Sheet Income Statement
A1: INFOSYS CONSOLIDATED INCOME STATEMENT
A3: Particulars | B3: FY2026 | C3: FY2025 | D3: Growth %
A4: Revenue from operations | B4: 178650 | C4: 162990 | D4: =(B4/C4)-1 -> 0.096079514
A5: Other income, net | B5: 4322 | C5: 3600 | D5: =(B5/C5)-1 -> 0.20055556
A6: Total income | B6: 182972 | C6: 166590 | D6: =(B6/C6)-1 -> 0.098337235
A7: Employee benefit expenses | B7: 95094 | C7: 85950 | D7: =(B7/C7)-1 -> 0.10638743
A8: Cost of technical sub-contractors | B8: 15421 | C8: 12937 | D8: =(B8/C8)-1 -> 0.19200742
A9: Travel expenses | B9: 2097 | C9: 1894 | D9: =(B9/C9)-1 -> 0.10718057
A10: Cost of software packages and others | B10: 15722 | C10: 15911 | D10: =(B10/C10)-1 -> -0.011878575
A11: Communication expenses | B11: 603 | C11: 620 | D11: =(B11/C11)-1 -> -0.027419355
A12: Consultancy and professional charges | B12: 2090 | C12: 1655 | D12: =(B12/C12)-1 -> 0.26283988
A13: Depreciation and amortization expenses | B13: 4902 | C13: 4812 | D13: =(B13/C13)-1 -> 0.018703242
A14: Finance cost | B14: 416 | C14: 416 | D14: =(B14/C14)-1 -> 0
A15: Other expenses | B15: 5343 | C15: 4787 | D15: =(B15/C15)-1 -> 0.1161479
... A17: Profit before exceptional item and tax | B17: 41284 | C17: 37608 | D17: =(B17/C17)-1 -> 0.097745161
A18: Exceptional item | B18: 1289 | C18: 0 | D18: ="N/A" -> N/A
A19: Profit before tax | B19: 39995 | C19: 37608 | D19: =(B19/C19)-1 -> 0.063470538
A20: Current tax | B20: 11767 | C20: 12130 | D20: =(B20/C20)-1 -> -0.029925804
A21: Deferred tax | B21: -1246 | C21: -1272 | D21: =(B21/C21)-1 -> -0.020440252
A22: Profit for the year | B22: 29474 | C22: 26750 | D22: =(B22/C22)-1 -> 0.10183178

Sheet Balance Sheet
A1: INFOSYS CONSOLIDATED BALANCE SHEET
A3: Particulars | B3: FY2026 | C3: FY2025 | D3: Growth %
A4: Property, plant and equipment | B4: 12651 | C4: 11778 | D4: =(B4/C4)-1 -> 0.074121243
A5: Right-of-use assets | B5: 6177 | C5: 6311 | D5: =(B5/C5)-1 -> -0.021232768
A6: Capital work-in-progress | B6: 526 | C6: 814 | D6: =(B6/C6)-1 -> -0.35380835
A7: Goodwill | B7: 12117 | C7: 10106 | D7: =(B7/C7)-1 -> 0.1989907
A8: Other intangible assets | B8: 2825 | C8: 2766 | D8: =(B8/C8)-1 -> 0.021330441
A9: Non-current investments | B9: 8930 | C9: 11059 | D9: =(B9/C9)-1 -> -0.19251289
A10: Non-current loans | B10: 6 | C10: 16 | D10: =(B10/C10)-1 -> -0.625
A11: Other non-current financial assets | B11: 2776 | C11: 3511 | D11: =(B11/C11)-1 -> -0.20934207
A12: Deferred tax assets | B12: 2264 | C12: 1108 | D12: =(B12/C12)-1 -> 1.0433213
A13: Income tax assets | B13: 666 | C13: 1622 | D13: =(B13/C13)-1 -> -0.58939581
A14: Other non-current assets | B14: 3540 | C14: 2713 | D14: =(B14/C14)-1 -> 0.3048286
A15: Total non-current assets | B15: 52478 | C15: 51804 | D15: =(B15/C15)-1 -> 0.013010578
... A22: Other current assets | B22: 15145 | C22: 11940 | D22: =(B22/C22)-1 -> 0.26842546
A23: Total current assets | B23: 103489 | C23: 97099 | D23: =(B23/C23)-1 -> 0.065809123 | I23: S
A24: Total assets | B24: 155967 | C24: 148903 | D24: =(B24/C24)-1 -> 0.04744028
A25: Equity share capital | B25: 2024 | C25: 2073 | D25: =(B25/C25)-1 -> -0.023637241
A26: Other equity | B26: 90828 | C26: 93745 | D26: =(B26/C26)-1 -> -0.031116326
A27: Non-controlling interests | B27: 445 | C27: 385 | D27: =(B27/C27)-1 -> 0.15584416
A28: Total equity | B28: 93297 | C28: 96203 | D28: =(B28/C28)-1 -> -0.030206958
A29: Non-current lease liabilities | B29: 6016 | C29: 5772 | D29: =(B29/C29)-1 -> 0.042273042
A30: Other non-current financial liabilities | B30: 2092 | C30: 2141 | D30: =(B30/C30)-1 -> -0.022886502
A31: Deferred tax liabilities | B31: 1679 | C31: 1722 | D31: =(B31/C31)-1 -> -0.024970964
A32: Other non-current liabilities | B32: 561 | C32: 215 | D32: =(B32/C32)-1 -> 1.6093023
A33: Total non-current liabilities | B33: 10348 | C33: 9850 | D33: =(B33/C33)-1 -> 0.050558376
A34: Current lease liabilities | B34: 3160 | C34: 2455 | D34: =(B34/C34)-1 -> 0.28716904
A35: Trade payables | B35: 4744 | C35: 4164 | D35: =(B35/C35)-1 -> 0.13928915
... A41: Total equity and liabilities | B41: 155967 | C41: 148903 | D41: =(B41/C41)-1 -> 0.04744028

Sheet Cash Flow Statement
A1: INFOSYS CONSOLIDATED CASH FLOW STATEMENT
A3: Particulars | B3: FY2026 | C3: FY2025 | D3: Growth %
A4: Cash flow from operating activities | B4: - | C4: -
A5: Profit for the year | B5: 29474 | C5: 26750 | D5: =IF(OR(C5="-",C5=0),"N/A",(B5/C5)-1) -> 0.10183178
A6: Income tax expense | B6: 10521 | C6: 10858 | D6: =IF(OR(C6="-",C6=0),"N/A",(B6/C6)-1) -> -0.031037023
A7: Depreciation and amortization | B7: 4902 | C7: 4812 | D7: =IF(OR(C7="-",C7=0),"N/A",(B7/C7)-1) -> 0.018703242
A8: Interest and dividend income | B8: -2630 | C8: -2570 | D8: =IF(OR(C8="-",C8=0),"N/A",(B8/C8)-1) -> 0.023346304
A9: Finance cost | B9: 416 | C9: 416 | D9: =IF(OR(C9="-",C9=0),"N/A",(B9/C9)-1) -> 0
A10: Impairment loss | B10: 33 | C10: 48 | D10: =IF(OR(C10="-",C10=0),"N/A",(B10/C10)-1) -> -0.3125
A11: Exchange differences | B11: 954 | C11: 79 | D11: =IF(OR(C11="-",C11=0),"N/A",(B11/C11)-1) -> 11.075949
A12: Stock compensation expense | B12: 952 | C12: 802 | D12: =IF(OR(C12="-",C12=0),"N/A",(B12/C12)-1) -> 0.18703242
A13: Interest receivable on income tax refund | B13: -63 | C13: -327 | D13: =IF(OR(C13="-",C13=0),"N/A",(B13/C13)-1) -> -0.80733945
A14: Provision for post-sale client support | B14: -167 | C14: -110 | D14: =IF(OR(C14="-",C14=0),"N/A",(B14/C14)-1) -> 0.51818182
A15: Other adjustments | B15: 881 | C15: 833 | D15: =IF(OR(C15="-",C15=0),"N/A",(B15/C15)-1) -> 0.057623049
A16: Changes in assets and liabilities | B16: - | C16: - | D16: =IF(OR(C16="-",C16=0),"N/A",(B16/C16)-1) -> N/A
A17: Trade receivables and unbilled revenue | B17: -5177 | C17: -1769 | D17: =IF(OR(C17="-",C17=0),"N/A",(B17/C17)-1) -> 1.9265122
A18: Loans, other financial assets and other assets | B18: -2645 | C18: -1024 | D18: =IF(OR(C18="-",C18=0),"N/A",(B18/C18)-1) -> 1.5830078
A19: Trade payables | B19: -26 | C19: 176 | D19: =IF(OR(C19="-",C19=0),"N/A",(B19/C19)-1) -> -1.1477273
A20: Other financial liabilities, other liabilities and provisions | B20: 5209 | C20: 2322 | D20: =IF(OR(C20="-",C20=0),"N/A",(B20/C20)-1) -> 1.2433247
A21: Cash generated from operations | B21: 42634 | C21: 41296 | D21: =IF(OR(C21="-",C21=0),"N/A",(B21/C21)-1) -> 0.032400232
A22: Income taxes paid | B22: -8648 | C22: -5602 | D22: =IF(OR(C22="-",C22=0),"N/A",(B22/C22)-1) -> 0.54373438
A23: Net cash generated by operating activities | B23: 33986 | C23: 35694 | D23: =IF(OR(C23="-",C23=0),"N/A",(B23/C23)-1) -> -0.047851179
A24: Cash flows from investing activities | B24: - | C24: - | D24: =IF(OR(C24="-",C24=0),"N/A",(B24/C24)-1) -> N/A
A25: Capital expenditure and intangibles | B25: -2727 | C25: -2237 | D25: =IF(OR(C25="-",C25=0),"N/A",(B25/C25)-1) -> 0.21904336
A26: Deposits placed with Corporation | B26: -944 | C26: -1225 | D26: =IF(OR(C26="-",C26=0),"N/A",(B26/C26)-1) -> -0.22938776
A27: Redemption of deposits | B27: 725 | C27: 776 | D27: =IF(OR(C27="-",C27=0),"N/A",(B27/C27)-1) -> -0.065721649
A28: Interest and dividend received | B28: 2713 | C28: 2040 | D28: =IF(OR(C28="-",C28=0),"N/A",(B28/C28)-1) -> 0.32990196
A29: Acquisition of business | B29: -637 | C29: -3155 | D29: =IF(OR(C29="-",C29=0),"N/A",(B29/C29)-1) -> -0.79809826
A30: Payment of contingent consideration | B30: -13 | C30: 0 | D30: =IF(OR(C30="-",C30=0),"N/A",(B30/C30)-1) -> N/A
A31: Escrow and other deposits pertaining to buyback | B31: -1815 | C31: 0 | D31: =IF(OR(C31="-",C31=0),"N/A",(B31/C31)-1) -> N/A
A32: Redemption of escrow and other deposits | B32: 1815 | C32: 0 | D32: =IF(OR(C32="-",C32=0),"N/A",(B32/C32)-1) -> N/A
A33: Other receipts | B33: 15 | C33: 10 | D33: =IF(OR(C33="-",C33=0),"N/A",(B33/C33)-1) -> 0.5
A34: Payments to acquire investments | B34: -96656 | C34: -89731 | D34: =IF(OR(C34="-",C34=0),"N/A",(B34/C34)-1) -> 0.077175112
A35: Proceeds on sale of investments | B35: 99470 | C35: 91576 | D35: =IF(OR(C35="-",C35=0),"N/A",(B35/C35)-1) -> 0.086201625
A36: Net cash generated / (used in) investing activities | B36: 1946 | C36: -1946 | D36: =IF(OR(C36="-",C36=0),"N/A",(B36/C36)-1) -> -2
A37: Cash flows from financing activities | B37: - | C37: - | D37: =IF(OR(C37="-",C37=0),"N/A",(B37/C37)-1) -> N/A
A38: Payment of lease liabilities | B38: -2824 | C38: -2824 | D38: =IF(OR(C38="-",C38=0),"N/A",(B38/C38)-1) -> 0
A39: Payment of dividends | B39: -18653 | C39: -20287 | D39: =IF(OR(C39="-",C39=0),"N/A",(B39/C39)-1) -> -0.080544191
A40: Loan repayment | B40: 0 | C40: -985 | D40: =IF(OR(C40="-",C40=0),"N/A",(B40/C40)-1) -> -1
A41: Dividend to non-controlling interest | B41: -3 | C41: -2 | D41: =IF(OR(C41="-",C41=0),"N/A",(B41/C41)-1) -> 0.5
...

Sheet 3-Statement Model
A1: INFOSYS 3-STATEMENT FINANCIAL MODEL
A3: Particulars | B3: FY2026 | C3: FY2025 | D3: FY2027 | E3: FY2028 | F3: FY2029
A4: INCOME STATEMENT
A5: Revenue from operations | B5: ='Income Statement'!B4 -> 178650 | C5: ='Income Statement'!C4 -> 162990 | D5: =B5*(1+Assumptions!B4) -> 192942 | E5: =D5*(1+Assumptions!C4) -> 208377.36 | F5: =E5*(1+Assumptions!D4) -> 225047.55
A6: Other income | B6: ='Income Statement'!B5 -> 4322 | C6: ='Income Statement'!C5 -> 3600 | D6: =D5*Assumptions!B5 -> 4630.608 | E6: =E5*Assumptions!C5 -> 5001.0566 | F6: =F5*Assumptions!D5 -> 5401.1412
A7: Total income | B7: ='Income Statement'!B6 -> 182972 | C7: ='Income Statement'!C6 -> 166590 | D7: =D5+D6 -> 197572.61 | E7: =E5+E6 -> 213378.42 | F7: =F5+F6 -> 230448.69
A8: Employee benefit expenses | B8: ='Income Statement'!B7 -> 95094 | C8: ='Income Statement'!C7 -> 85950 | D8: =D5*Assumptions!B6 -> 102645.14 | E8: =E5*Assumptions!C6 -> 110856.76 | F8: =F5*Assumptions!D6 -> 119725.3
A9: Cost of technical sub-contractors | B9: ='Income Statement'!B8 -> 15421 | C9: ='Income Statement'!C8 -> 12937 | D9: =D5*($B$9/$B$5) -> 16654.68 | E9: =E5*($B$9/$B$5) -> 17987.054 | F9: =F5*($B$9/$B$5) -> 19426.019
A10: Travel expenses | B10: ='Income Statement'!B9 -> 2097 | C10: ='Income Statement'!C9 -> 1894 | D10: =D5*($B$10/$B$5) -> 2264.76 | E10: =E5*($B$10/$B$5) -> 2445.9408 | F10: =E5*($B$10/$B$5) -> 2445.9408
A11: Cost of software packages and others | B11: ='Income Statement'!B10 -> 15722 | C11: ='Income Statement'!C10 -> 15911 | D11: =D5*($B$11/$B$5) -> 16979.76 | E11: =E5*($B$11/$B$5) -> 18338.141 | F11: =F5*($B$11/$B$5) -> 19805.192
A12: Communication expenses | B12: ='Income Statement'!B11 -> 603 | C12: ='Income Statement'!C11 -> 620 | D12: =D5*($B$12/$B$5) -> 651.24 | E12: =E5*($B$12/$B$5) -> 703.3392 | F12: =F5*($B$12/$B$5) -> 759.60634
A13: Consultancy and professional charges | B13: ='Income Statement'!B12 -> 2090 | C13: ='Income Statement'!C12 -> 1655 | D13: =D5*($B$13/$B$5) -> 2257.2 | E13: =E5*($B$13/$B$5) -> 2437.776 | F13: =F5*($B$13/$B$5) -> 2632.7981
A14: Depreciation and amortization expenses | B14: ='Income Statement'!B13 -> 4902 | C14: ='Income Statement'!C13 -> 4812 | D14: =D5*Assumptions!B8 -> 5209.434 | E14: =E5*Assumptions!C8 -> 5626.1887 | F14: =F5*Assumptions!D8 -> 6076.2838
A15: Finance cost | B15: ='Income Statement'!B14 -> 416 | C15: ='Income Statement'!C14 -> 416 | D15: =D5*Assumptions!B9 -> 385.884 | E15: =E5*Assumptions!C9 -> 416.75472 | F15: =F5*Assumptions!D9 -> 450.0951
A16: Other expenses | B16: ='Income Statement'!B15 -> 5343 | C16: ='Income Statement'!C15 -> 4787 | D16: =D5*($B$16/$B$5) -> 5770.44 | E16: =E5*($B$16/$B$5) -> 6232.0752 | F16: =F5*($B$16/$B$5) -> 6730.6412
A17: Total expenses | B17: ='Income Statement'!B16 -> 141688 | C17: ='Income Statement'!C16 -> 128982 | D17: =SUM(D8:D16) -> 152818.54 | E17: =SUM(E8:E16) -> 165044.03 | F17: =SUM(F8:F16) -> 178051.87
A18: Profit before exceptional item and tax | B18: ='Income Statement'!B17 -> 41284 | C18: ='Income Statement'!C17 -> 37608 | D18: =D7-D17 -> 44754.066 | E18: =E7-E17 -> 48334.391 | F18: =F7-F17 -> 52396.818
A19: Exceptional item | B19: ='Income Statement'!B18 -> 1289 | C19: ='Income Statement'!C18 -> 0 | D19: =0 -> 0 | E19: =0 -> 0 | F19: =0 -> 0
A20: Profit before tax | B20: ='Income Statement'!B19 -> 39995 | C20: ='Income Statement'!C19 -> 37608 | D20: =D18+D19 -> 44754.066 | E20: =E18+E19 -> 48334.391 | F20: =F18+F19 -> 52396.818
A21: Current tax | B21: ='Income Statement'!B20 -> 11767 | C21: ='Income Statement'!C20 -> 12130 | D21: =D20*Assumptions!B10 -> 11770.319 | E21: =E20*Assumptions!C10 -> 12711.945 | F21: =F20*Assumptions!D10 -> 13780.363
A22: Deferred tax | B22: ='Income Statement'!B21 -> -1246 | C22: ='Income Statement'!C21 -> -1272 | D22: =0 -> 0 | E22: =0 -> 0 | F22: =0 -> 0
A23: Profit for the year | B23: ='Income Statement'!B22 -> 29474 | C23: ='Income Statement'!C22 -> 26750 | D23: =D20-D21+D22 -> 32983.747 | E23: =E20-E21+E22 -> 35622.446 | F23: =F20-F21+F22 -> 38616.455
A25: BALANCE SHEET
A26: Property, plant and equipment | B26: ='Balance Sheet'!B4 -> 12651 | C26: ='Balance Sheet'!C4 -> 11778 | D26: =B26-D87-D14 -> 10335.696 | E26: =C26-E87-E14 -> 9277.4717 | F26: =D26-F87-F14 -> 7635.1254
A27: Right-of-use assets | B27: ='Balance Sheet'!B5 -> 6177 | C27: ='Balance Sheet'!C5 -> 6311 | D27: =D5*($B$27/$B$5) -> 6671.16 | E27: =E5*($B$27/$B$5) -> 7204.8528 | F27: =F5*($B$27/$B$5) -> 7781.241
A28: Capital work-in-progress | B28: ='Balance Sheet'!B6 -> 526 | C28: ='Balance Sheet'!C6 -> 814 | D28: =D5*($B$28/$B$5) -> 568.08 | E28: =E5*($B$28/$B$5) -> 613.5264 | F28: =F5*($B$28/$B$5) -> 662.60851
A29: Goodwill | B29: ='Balance Sheet'!B7 -> 12117 | C29: ='Balance Sheet'!C7 -> 10106 | D29: =D5*($B$29/$B$5) -> 13086.36 | E29: =E5*($B$29/$B$5) -> 14133.269 | F29: =F5*($B$29/$B$5) -> 15263.93
A30: Other intangible assets | B30: ='Balance Sheet'!B8 -> 2825 | C30: ='Balance Sheet'!C8 -> 2766 | D30: =D5*($B$30/$B$5) -> 3051 | E30: =E5*($B$30/$B$5) -> 3295.08 | F30: =F5*($B$30/$B$5) -> 3558.6864
A31: Non-current investments | B31: ='Balance Sheet'!B9 -> 8930 | C31: ='Balance Sheet'!C9 -> 11059 | D31: =D5*($B$31/$B$5) -> 9644.4 | E31: =E5*($B$31/$B$5) -> 10415.952 | F31: =F5*($B$31/$B$5) -> 11249.228
A32: Non-current loans | B32: ='Balance Sheet'!B10 -> 6 | C32: ='Balance Sheet'!C10 -> 16 | D32: =D5*($B$32/$B$5) -> 6.48 | E32: =E5*($B$32/$B$5) -> 6.9984 | F32: =F5*($B$32/$B$5) -> 7.558272
A33: Other non-current financial assets | B33: ='Balance Sheet'!B11 -> 2776 | C33: ='Balance Sheet'!C11 -> 3511 | D33: =D5*($B$33/$B$5) -> 2998.08 | E33: =E5*($B$33/$B$5) -> 3237.9264 | F33: =F5*($B$33/$B$5) -> 3496.9605
A34: Deferred tax assets | B34: ='Balance Sheet'!B12 -> 2264 | C34: ='Balance Sheet'!C12 -> 1108 | D34: =D5*($B$34/$B$5) -> 2445.12 | E34: =E5*($B$34/$B$5) -> 2640.7296 | F34: =F5*($B$34/$B$5) -> 2851.988
A35: Income tax assets | B35: ='Balance Sheet'!B13 -> 666 | C35: ='Balance Sheet'!C13 -> 1622 | D35: =D5*($B$35/$B$5) -> 719.28 | E35: =E5*($B$35/$B$5) -> 776.8224 | F35: =F5*($B$35/$B$5) -> 838.96819
A36: Other non-current assets | B36: ='Balance Sheet'!B14 -> 3540 | C36: ='Balance Sheet'!C14 -> 2713 | D36: =D5*($B$36/$B$5) -> 3823.2 | E36: =E5*($B$36/$B$5) -> 4129.056 | F36: =F5*($B$36/$B$5) -> 4459.3805
A37: Total non-current assets | B37: ='Balance Sheet'!B15 -> 52478 | C37: ='Balance Sheet'!C15 -> 51804 | D37: =SUM(D26:D36) -> 53348.856 | E37: =SUM(E26:E36) -> 55731.684 | F37: =SUM(F26:F36) -> 57805.675
A38: Current investments | B38: ='Balance Sheet'!B16 -> 12950 | C38: ='Balance Sheet'!C16 -> 12482 | D38: =D5*($B$38/$B$5) -> 13986 | E38: =E5*($B$38/$B$5) -> 15104.88 | F38: =F5*($B$38/$B$5) -> 16313.27
A39: Trade receivables | B39: ='Balance Sheet'!B17 -> 35234 | C39: ='Balance Sheet'!C17 -> 31158 | D39: =D5*Assumptions!B12 -> 38009.574 | E39: =E5*Assumptions!C12 -> 41050.34 | F39: =F5*Assumptions!D12 -> 44334.367
A40: Cash and cash equivalents | B40: ='Balance Sheet'!B18 -> 22201 | C40: ='Balance Sheet'!C18 -> 24455 | D40: =D111 -> 32173.75 | E40: =E111 -> 32074.97 | F40: =F111 -> 38680.617
A41: Current loans | B41: ='Balance Sheet'!B19 -> 234 | C41: ='Balance Sheet'!C19 -> 249 | D41: =D5*($B$41/$B$5) -> 252.72 | E41: =E5*($B$41/$B$5) -> 272.9376 | F41: =F5*($B$41/$B$5) -> 294.77261
A42: Other current financial assets | B42: ='Balance Sheet'!B20 -> 15890 | C42: ='Balance Sheet'!C20 -> 13840 | D42: =D5*($B$42/$B$5) -> 17161.2 | E42: =E5*($B$42/$B$5) -> 18534.096 | F42: =F5*($B$42/$B$5) -> 20016.824
...

Sheet Analysis
A1: INFOSYS FINANCIAL ANALYSIS
A3: Metric | B3: FY2026 | C3: FY2027 | D3: FY2028 | E3: FY2029
A4: Revenue Growth | B4: ='3-Statement Model'!B5/'3-Statement Model'!C5-1 -> 0.096079514 | C4: ='3-Statement Model'!D5/'3-Statement Model'!B5-1 -> 0.08 | D4: ='3-Statement Model'!E5/'3-Statement Model'!D5-1 -> 0.08 | E4: ='3-Statement Model'!F5/'3-Statement Model'!E5-1 -> 0.08
A5: Net Profit Margin | B5: ='3-Statement Model'!B23/'3-Statement Model'!B5 -> 0.16498181 | C5: ='3-Statement Model'!D23/'3-Statement Model'!D5 -> 0.17095162 | D5: ='3-Statement Model'!D23/'3-Statement Model'!D5 -> 0.17095162 | E5: ='3-Statement Model'!F23/'3-Statement Model'!F5 -> 0.17159243
A6: Operating Margin | B6: ='3-Statement Model'!B18/'3-Statement Model'!B5 -> 0.23108872 | C6: ='3-Statement Model'!D18/'3-Statement Model'!D5 -> 0.23195606 | D6: ='3-Statement Model'!E18/'3-Statement Model'!E5 -> 0.23195606 | E6: ='3-Statement Model'!F18/'3-Statement Model'!F5 -> 0.23282554
A7: ROE | B7: ='3-Statement Model'!B23/'3-Statement Model'!B50 -> 0.31591584 | C7: ='3-Statement Model'!D23/'3-Statement Model'!D50 -> 0.31263923 | D7: ='3-Statement Model'!E23/'3-Statement Model'!E50 -> 0.32566621 | E7: ='3-Statement Model'!F23/'3-Statement Model'!F50 -> 0.32237042
A8: ROA | B8: ='3-Statement Model'!B23/'3-Statement Model'!B46 -> 0.18897587 | C8: ='3-Statement Model'!D23/'3-Statement Model'!D46 -> 0.19035985 | D8: ='3-Statement Model'!E23/'3-Statement Model'!E46 -> 0.19511197 | E8: ='3-Statement Model'!F23/'3-Statement Model'!F46 -> 0.19421314
A9: Current Ratio | B9: ='3-Statement Model'!B45/'3-Statement Model'!B62 -> 1.9779252 | C9: ='3-Statement Model'!D45/'3-Statement Model'!D62 -> 2.1189938 | D9: ='3-Statement Model'!E45/'3-Statement Model'!E62 -> 2.0752662 | E9: ='3-Statement Model'!F45/'3-Statement Model'!F62 -> 2.136463
A10: Debt-to-Equity | B10: =('3-Statement Model'!B51+'3-Statement Model'!B56)/'3-Statement Model'!B50 -> 0.098352573 | C10: =('3-Statement Model'!D51+'3-Statement Model'!D56)/'3-Statement Model'!D50 -> 0.093933529 | D10: =('3-Statement Model'!E51+'3-Statement Model'!E56)/'3-Statement Model'!E50 -> 0.097847532 | E10: =('3-Statement Model'!F51+'3-Statement Model'!F56)/'3-Statement Model'!F50 -> 0.096495589
A11: CFO / Net Profit | B11: ='3-Statement Model'!B85/'3-Statement Model'!B23 -> 1.1530841 | C11: ='3-Statement Model'!D85/'3-Statement Model'!D23 -> 1.0916007 | D11: ='3-Statement Model'!E85/'3-Statement Model'!E23 -> 0.7889839 | E11: ='3-Statement Model'!F85/'3-Statement Model'!F23 -> 1.0086644
A12: Free Cash Flow | B12: ='3-Statement Model'!B85+'3-Statement Model'!B87 -> 31259 | C12: ='3-Statement Model'!D85+'3-Statement Model'!D87 -> 33110.951 | D12: ='3-Statement Model'!E85+'3-Statement Model'!E87 -> 24979.876 | E12: ='3-Statement Model'!F85+'3-Statement Model'!F87 -> 35575.329
A13: FCF Margin | B13: =B12/'3-Statement Model'!B5 -> 0.17497341 | C13: =C12/'3-Statement Model'!D5 -> 0.1716109 | D13: =D12/'3-Statement Model'!E5 -> 0.11987807 | E13: =E12/'3-Statement Model'!F5 -> 0.15807917
A14: Dividend Payout Ratio | B14: =-'3-Statement Model'!B101/'3-Statement Model'!B23 -> 0.63286286 | C14: =Assumptions!B14 -> 0.63 | D14: =Assumptions!C14 -> 0.63 | E14: =Assumptions!D14 -> 0.63
A15: Ending Cash | B15: ='3-Statement Model'!B111 -> 22201 | C15: ='3-Statement Model'!D111 -> 32173.75 | D15: ='3-Statement Model'!E111 -> 32074.97 | E15: ='3-Statement Model'!F111 -> 38680.617
A18: KEY MODEL CHECKS
A20: Balance Sheet Check | B20: ='3-Statement Model'!B63-'3-Statement Model'!B46 -> 0 | C20: ='3-Statement Model'!D63-'3-Statement Model'!D46 -> 0 | D20: ='3-Statement Model'!E63-'3-Statement Model'!E46 -> 0 | E20: ='3-Statement Model'!F63-'3-Statement Model'!F46 -> 0
A21: Cash Flow Check | B21: ='3-Statement Model'!B111-'3-Statement Model'!B40 -> 0 | C21: ='3-Statement Model'!C111-'3-Statement Model'!C40 -> 0 | D21: ='3-Statement Model'!D111-'3-Statement Model'!D40 -> 0 | E21: ='3-Statement Model'!E111-'3-Statement Model'!E40 -> 0
A22: Forecast Revenue Growth Check | B22: ='3-Statement Model'!B5/'3-Statement Model'!C5-1 -> 0.096079514 | C22: ='3-Statement Model'!D5/'3-Statement Model'!B5-1 -> 0.08 | D22: ='3-Statement Model'!E5/'3-Statement Model'!D5-1 -> 0.08 | E22: ='3-Statement Model'!F5/'3-Statement Model'!E5-1 -> 0.08
A23: Forecast Dividend Payout Check | B23: =-'3-Statement Model'!B101/'3-Statement Model'!B23 -> 0.63286286 | C23: =Assumptions!B14 -> 0.63 | D23: =-'3-Statement Model'!D101/'3-Statement Model'!D23 -> 0.63 | E23: =Assumptions!D14 -> 0.63
A26: MODEL INTERPRETATION
A27: 1. Revenue is forecast to grow at 8% annually from FY2027 to FY2029.
A28: 2. Net profit margin remains around 17% throughout the forecast period.
A29: 3. Operating margin remains broadly stable at approximately 23%.
A30: 4. Current ratio remains above 2.0x across the forecast period.
A31: 5. Free cash flow remains positive, while ending cash increases from ₹22,201 crore in FY2026 to ₹38,681 crore in FY2029.
A34: CHART SUPPORTING DATA
A35: Metric | B35: FY2026 | C35: FY2027 | D35: FY2028 | E35: FY2029
A36: Free Cash Flow | B36: 31259 | C36: 33111 | D36: 24980 | E36: 35575
A37: Ending Cash | B37: 22201 | C37: 32174 | D37: 32075 | E37: 38681
